[2019-10-18 18:11:09,657][Thread-1:6768][task_id:django.request][log.py:228][ERROR][Internal Server Error: /api/setting/recharge/save]
Traceback (most recent call last):
  File "D:\WorkSpase\Python\three_server\venv\lib\site-packages\django\db\models\query.py", line 554, in update_or_create
    obj = self.select_for_update().get(**kwargs)
  File "D:\WorkSpase\Python\three_server\venv\lib\site-packages\django\db\models\query.py", line 408, in get
    self.model._meta.object_name
system.models.keyValue.KeyValue.DoesNotExist: KeyValue matching query does not exist.

During handling of the above exception, another exception occurred:

Traceback (most recent call last):
  File "D:\WorkSpase\Python\three_server\venv\lib\site-packages\django\db\backends\utils.py", line 84, in _execute
    return self.cursor.execute(sql, params)
psycopg2.errors.StringDataRightTruncation: 错误:  对于可变字符类型来说，值太长了(24)


The above exception was the direct cause of the following exception:

Traceback (most recent call last):
  File "D:\WorkSpase\Python\three_server\venv\lib\site-packages\django\core\handlers\exception.py", line 34, in inner
    response = get_response(request)
  File "D:\WorkSpase\Python\three_server\venv\lib\site-packages\django\core\handlers\base.py", line 115, in _get_response
    response = self.process_exception_by_middleware(e, request)
  File "D:\WorkSpase\Python\three_server\venv\lib\site-packages\django\core\handlers\base.py", line 113, in _get_response
    response = wrapped_callback(request, *callback_args, **callback_kwargs)
  File "D:\WorkSpase\Python\three_server\venv\lib\site-packages\django\views\generic\base.py", line 71, in view
    return self.dispatch(request, *args, **kwargs)
  File "D:\WorkSpase\Python\three_server\three_server\base\controller.py", line 98, in dispatch
    return handler()
  File "D:\WorkSpase\Python\three_server\game_setting\api\server_recharge.py", line 26, in save
    create(json.dumps(form.data))
  File "D:\WorkSpase\Python\three_server\game_setting\biz\server_recharge.py", line 32, in create
    value=value
  File "D:\WorkSpase\Python\three_server\system\models\keyValue.py", line 38, in set_value
    KeyValue.objects.update_or_create(key=data['key'], type=data['type'], defaults={'value': data['value']})
  File "D:\WorkSpase\Python\three_server\venv\lib\site-packages\django\db\models\manager.py", line 82, in manager_method
    return getattr(self.get_queryset(), name)(*args, **kwargs)
  File "D:\WorkSpase\Python\three_server\venv\lib\site-packages\django\db\models\query.py", line 559, in update_or_create
    obj, created = self._create_object_from_params(kwargs, params, lock=True)
  File "D:\WorkSpase\Python\three_server\venv\lib\site-packages\django\db\models\query.py", line 575, in _create_object_from_params
    obj = self.create(**params)
  File "D:\WorkSpase\Python\three_server\venv\lib\site-packages\django\db\models\query.py", line 422, in create
    obj.save(force_insert=True, using=self.db)
  File "D:\WorkSpase\Python\three_server\venv\lib\site-packages\django\db\models\base.py", line 741, in save
    force_update=force_update, update_fields=update_fields)
  File "D:\WorkSpase\Python\three_server\venv\lib\site-packages\django\db\models\base.py", line 779, in save_base
    force_update, using, update_fields,
  File "D:\WorkSpase\Python\three_server\venv\lib\site-packages\django\db\models\base.py", line 870, in _save_table
    result = self._do_insert(cls._base_manager, using, fields, update_pk, raw)
  File "D:\WorkSpase\Python\three_server\venv\lib\site-packages\django\db\models\base.py", line 908, in _do_insert
    using=using, raw=raw)
  File "D:\WorkSpase\Python\three_server\venv\lib\site-packages\django\db\models\manager.py", line 82, in manager_method
    return getattr(self.get_queryset(), name)(*args, **kwargs)
  File "D:\WorkSpase\Python\three_server\venv\lib\site-packages\django\db\models\query.py", line 1186, in _insert
    return query.get_compiler(using=using).execute_sql(return_id)
  File "D:\WorkSpase\Python\three_server\venv\lib\site-packages\django\db\models\sql\compiler.py", line 1335, in execute_sql
    cursor.execute(sql, params)
  File "D:\WorkSpase\Python\three_server\venv\lib\site-packages\django\db\backends\utils.py", line 99, in execute
    return super().execute(sql, params)
  File "D:\WorkSpase\Python\three_server\venv\lib\site-packages\django\db\backends\utils.py", line 67, in execute
    return self._execute_with_wrappers(sql, params, many=False, executor=self._execute)
  File "D:\WorkSpase\Python\three_server\venv\lib\site-packages\django\db\backends\utils.py", line 76, in _execute_with_wrappers
    return executor(sql, params, many, context)
  File "D:\WorkSpase\Python\three_server\venv\lib\site-packages\django\db\backends\utils.py", line 84, in _execute
    return self.cursor.execute(sql, params)
  File "D:\WorkSpase\Python\three_server\venv\lib\site-packages\django\db\utils.py", line 89, in __exit__
    raise dj_exc_value.with_traceback(traceback) from exc_value
  File "D:\WorkSpase\Python\three_server\venv\lib\site-packages\django\db\backends\utils.py", line 84, in _execute
    return self.cursor.execute(sql, params)
django.db.utils.DataError: 错误:  对于可变字符类型来说，值太长了(24)

[2019-10-18 18:11:09,669][MainThread:8628][task_id:django.channels.server][runserver.py:154][ERROR][HTTP POST /api/setting/recharge/save 500 [0.28, 127.0.0.1:14125]]
[2019-10-18 19:26:39,844][Thread-15:9956][task_id:django.request][log.py:228][ERROR][Internal Server Error: /api/setting/recharge/save]
Traceback (most recent call last):
  File "D:\WorkSpase\Python\three_server\venv\lib\site-packages\django\db\backends\utils.py", line 84, in _execute
    return self.cursor.execute(sql, params)
psycopg2.errors.StringDataRightTruncation: 错误:  对于可变字符类型来说，值太长了(200)


The above exception was the direct cause of the following exception:

Traceback (most recent call last):
  File "D:\WorkSpase\Python\three_server\venv\lib\site-packages\django\core\handlers\exception.py", line 34, in inner
    response = get_response(request)
  File "D:\WorkSpase\Python\three_server\venv\lib\site-packages\django\core\handlers\base.py", line 115, in _get_response
    response = self.process_exception_by_middleware(e, request)
  File "D:\WorkSpase\Python\three_server\venv\lib\site-packages\django\core\handlers\base.py", line 113, in _get_response
    response = wrapped_callback(request, *callback_args, **callback_kwargs)
  File "D:\WorkSpase\Python\three_server\venv\lib\site-packages\django\views\generic\base.py", line 71, in view
    return self.dispatch(request, *args, **kwargs)
  File "D:\WorkSpase\Python\three_server\three_server\base\controller.py", line 98, in dispatch
    return handler()
  File "D:\WorkSpase\Python\three_server\game_setting\api\server_recharge.py", line 26, in save
    create(json.dumps(form.data))
  File "D:\WorkSpase\Python\three_server\game_setting\biz\server_recharge.py", line 34, in create
    value=value
  File "D:\WorkSpase\Python\three_server\system\models\keyValue.py", line 39, in set_value
    KeyValue.objects.update_or_create(key=data['key'], type=data['type'], defaults={'value': data['value']})
  File "D:\WorkSpase\Python\three_server\venv\lib\site-packages\django\db\models\manager.py", line 82, in manager_method
    return getattr(self.get_queryset(), name)(*args, **kwargs)
  File "D:\WorkSpase\Python\three_server\venv\lib\site-packages\django\db\models\query.py", line 564, in update_or_create
    obj.save(using=self.db)
  File "D:\WorkSpase\Python\three_server\venv\lib\site-packages\django\db\models\base.py", line 741, in save
    force_update=force_update, update_fields=update_fields)
  File "D:\WorkSpase\Python\three_server\venv\lib\site-packages\django\db\models\base.py", line 779, in save_base
    force_update, using, update_fields,
  File "D:\WorkSpase\Python\three_server\venv\lib\site-packages\django\db\models\base.py", line 851, in _save_table
    forced_update)
  File "D:\WorkSpase\Python\three_server\venv\lib\site-packages\django\db\models\base.py", line 900, in _do_update
    return filtered._update(values) > 0
  File "D:\WorkSpase\Python\three_server\venv\lib\site-packages\django\db\models\query.py", line 760, in _update
    return query.get_compiler(self.db).execute_sql(CURSOR)
  File "D:\WorkSpase\Python\three_server\venv\lib\site-packages\django\db\models\sql\compiler.py", line 1429, in execute_sql
    cursor = super().execute_sql(result_type)
  File "D:\WorkSpase\Python\three_server\venv\lib\site-packages\django\db\models\sql\compiler.py", line 1100, in execute_sql
    cursor.execute(sql, params)
  File "D:\WorkSpase\Python\three_server\venv\lib\site-packages\django\db\backends\utils.py", line 99, in execute
    return super().execute(sql, params)
  File "D:\WorkSpase\Python\three_server\venv\lib\site-packages\django\db\backends\utils.py", line 67, in execute
    return self._execute_with_wrappers(sql, params, many=False, executor=self._execute)
  File "D:\WorkSpase\Python\three_server\venv\lib\site-packages\django\db\backends\utils.py", line 76, in _execute_with_wrappers
    return executor(sql, params, many, context)
  File "D:\WorkSpase\Python\three_server\venv\lib\site-packages\django\db\backends\utils.py", line 84, in _execute
    return self.cursor.execute(sql, params)
  File "D:\WorkSpase\Python\three_server\venv\lib\site-packages\django\db\utils.py", line 89, in __exit__
    raise dj_exc_value.with_traceback(traceback) from exc_value
  File "D:\WorkSpase\Python\three_server\venv\lib\site-packages\django\db\backends\utils.py", line 84, in _execute
    return self.cursor.execute(sql, params)
django.db.utils.DataError: 错误:  对于可变字符类型来说，值太长了(200)

[2019-10-18 19:26:39,853][MainThread:13464][task_id:django.channels.server][runserver.py:154][ERROR][HTTP POST /api/setting/recharge/save 500 [0.17, 127.0.0.1:5678]]
[2019-10-19 15:14:35,967][Thread-3:9012][task_id:django.request][log.py:228][ERROR][Internal Server Error: /api/setting/recharge/info]
Traceback (most recent call last):
  File "D:\WorkSpase\Python\three_server\venv\lib\site-packages\django\core\handlers\exception.py", line 34, in inner
    response = get_response(request)
  File "D:\WorkSpase\Python\three_server\venv\lib\site-packages\django\core\handlers\base.py", line 115, in _get_response
    response = self.process_exception_by_middleware(e, request)
  File "D:\WorkSpase\Python\three_server\venv\lib\site-packages\django\core\handlers\base.py", line 113, in _get_response
    response = wrapped_callback(request, *callback_args, **callback_kwargs)
  File "D:\WorkSpase\Python\three_server\venv\lib\site-packages\django\views\generic\base.py", line 71, in view
    return self.dispatch(request, *args, **kwargs)
  File "D:\WorkSpase\Python\three_server\three_server\base\controller.py", line 98, in dispatch
    return handler()
  File "D:\WorkSpase\Python\three_server\game_setting\api\server_recharge.py", line 30, in info
    data = info()
  File "D:\WorkSpase\Python\three_server\game_setting\biz\server_recharge.py", line 26, in info
    "info": json.loads(KeyValue.get_value(Keys.RECHARGE_TACTICS_INF.value))
  File "D:\WorkSpase\Python\three_server\system\models\keyValue.py", line 26, in get_value
    data = cls.objects.get(key=Keys[key].value)
  File "C:\Program Files\Python35\lib\enum.py", line 277, in __getitem__
    return cls._member_map_[name]
KeyError: 'RECHARGE_TACTICS_INFO'
[2019-10-19 15:14:35,972][MainThread:4352][task_id:django.channels.server][runserver.py:154][ERROR][HTTP GET /api/setting/recharge/info 500 [0.11, 127.0.0.1:2322]]
[2019-10-19 15:15:23,632][Thread-3:12104][task_id:django.request][log.py:228][ERROR][Internal Server Error: /api/setting/recharge/info]
Traceback (most recent call last):
  File "D:\WorkSpase\Python\three_server\venv\lib\site-packages\django\core\handlers\exception.py", line 34, in inner
    response = get_response(request)
  File "D:\WorkSpase\Python\three_server\venv\lib\site-packages\django\core\handlers\base.py", line 115, in _get_response
    response = self.process_exception_by_middleware(e, request)
  File "D:\WorkSpase\Python\three_server\venv\lib\site-packages\django\core\handlers\base.py", line 113, in _get_response
    response = wrapped_callback(request, *callback_args, **callback_kwargs)
  File "D:\WorkSpase\Python\three_server\venv\lib\site-packages\django\views\generic\base.py", line 71, in view
    return self.dispatch(request, *args, **kwargs)
  File "D:\WorkSpase\Python\three_server\three_server\base\controller.py", line 98, in dispatch
    return handler()
  File "D:\WorkSpase\Python\three_server\game_setting\api\server_recharge.py", line 30, in info
    data = info()
  File "D:\WorkSpase\Python\three_server\game_setting\biz\server_recharge.py", line 26, in info
    "info": json.loads(KeyValue.get_value(Keys.RECHARGE_TACTICS_INF.value))
  File "C:\Program Files\Python35\lib\enum.py", line 274, in __getattr__
    raise AttributeError(name) from None
AttributeError: RECHARGE_TACTICS_INF
[2019-10-19 15:15:23,636][MainThread:11064][task_id:django.channels.server][runserver.py:154][ERROR][HTTP GET /api/setting/recharge/info 500 [0.10, 127.0.0.1:2402]]
[2019-10-19 15:15:44,841][Thread-3:13068][task_id:django.request][log.py:228][ERROR][Internal Server Error: /api/setting/recharge/info]
Traceback (most recent call last):
  File "D:\WorkSpase\Python\three_server\venv\lib\site-packages\django\core\handlers\exception.py", line 34, in inner
    response = get_response(request)
  File "D:\WorkSpase\Python\three_server\venv\lib\site-packages\django\core\handlers\base.py", line 115, in _get_response
    response = self.process_exception_by_middleware(e, request)
  File "D:\WorkSpase\Python\three_server\venv\lib\site-packages\django\core\handlers\base.py", line 113, in _get_response
    response = wrapped_callback(request, *callback_args, **callback_kwargs)
  File "D:\WorkSpase\Python\three_server\venv\lib\site-packages\django\views\generic\base.py", line 71, in view
    return self.dispatch(request, *args, **kwargs)
  File "D:\WorkSpase\Python\three_server\three_server\base\controller.py", line 98, in dispatch
    return handler()
  File "D:\WorkSpase\Python\three_server\game_setting\api\server_recharge.py", line 30, in info
    data = info()
  File "D:\WorkSpase\Python\three_server\game_setting\biz\server_recharge.py", line 26, in info
    "info": json.loads(KeyValue.get_value(Keys.RECHARGE_TACTICS_INF.value))
  File "C:\Program Files\Python35\lib\enum.py", line 274, in __getattr__
    raise AttributeError(name) from None
AttributeError: RECHARGE_TACTICS_INF
[2019-10-19 15:15:44,847][MainThread:13204][task_id:django.channels.server][runserver.py:154][ERROR][HTTP GET /api/setting/recharge/info 500 [0.11, 127.0.0.1:2430]]
[2019-10-19 15:17:00,043][Thread-3:15388][task_id:django.request][log.py:228][ERROR][Internal Server Error: /api/setting/recharge/info]
Traceback (most recent call last):
  File "D:\WorkSpase\Python\three_server\venv\lib\site-packages\django\core\handlers\exception.py", line 34, in inner
    response = get_response(request)
  File "D:\WorkSpase\Python\three_server\venv\lib\site-packages\django\core\handlers\base.py", line 115, in _get_response
    response = self.process_exception_by_middleware(e, request)
  File "D:\WorkSpase\Python\three_server\venv\lib\site-packages\django\core\handlers\base.py", line 113, in _get_response
    response = wrapped_callback(request, *callback_args, **callback_kwargs)
  File "D:\WorkSpase\Python\three_server\venv\lib\site-packages\django\views\generic\base.py", line 71, in view
    return self.dispatch(request, *args, **kwargs)
  File "D:\WorkSpase\Python\three_server\three_server\base\controller.py", line 98, in dispatch
    return handler()
  File "D:\WorkSpase\Python\three_server\game_setting\api\server_recharge.py", line 30, in info
    data = info()
  File "D:\WorkSpase\Python\three_server\game_setting\biz\server_recharge.py", line 26, in info
    "info": json.loads(KeyValue.get_value(Keys.RECHARGE_TACTICS_INFO.value))
  File "C:\Program Files\Python35\lib\json\__init__.py", line 312, in loads
    s.__class__.__name__))
TypeError: the JSON object must be str, not 'dict'
[2019-10-19 15:17:00,047][MainThread:3232][task_id:django.channels.server][runserver.py:154][ERROR][HTTP GET /api/setting/recharge/info 500 [0.11, 127.0.0.1:2485]]
[2019-10-20 13:00:42,414][Thread-1:13720][task_id:django.request][log.py:228][ERROR][Internal Server Error: /three/finance/pay/recharge]
Traceback (most recent call last):
  File "D:\WorkSpase\Python\three_server\venv\lib\site-packages\django\core\handlers\exception.py", line 34, in inner
    response = get_response(request)
  File "D:\WorkSpase\Python\three_server\venv\lib\site-packages\django\core\handlers\base.py", line 115, in _get_response
    response = self.process_exception_by_middleware(e, request)
  File "D:\WorkSpase\Python\three_server\venv\lib\site-packages\django\core\handlers\base.py", line 113, in _get_response
    response = wrapped_callback(request, *callback_args, **callback_kwargs)
  File "D:\WorkSpase\Python\three_server\venv\lib\site-packages\django\views\generic\base.py", line 71, in view
    return self.dispatch(request, *args, **kwargs)
  File "D:\WorkSpase\Python\three_server\three_server\base\controller.py", line 98, in dispatch
    return handler()
  File "D:\WorkSpase\Python\three_server\finance\api\client_pay.py", line 119, in recharge
    test(10)
  File "D:\WorkSpase\Python\three_server\finance\biz\server_recharge_record.py", line 44, in test
    if info['range'][0] < now_time < info['range'][0]:
TypeError: string indices must be integers
[2019-10-20 13:00:42,419][MainThread:11360][task_id:django.channels.server][runserver.py:154][ERROR][HTTP GET /three/finance/pay/recharge 500 [0.18, 127.0.0.1:3068]]
[2019-10-20 13:01:20,618][Thread-1:18712][task_id:django.request][log.py:228][ERROR][Internal Server Error: /three/finance/pay/recharge]
Traceback (most recent call last):
  File "D:\WorkSpase\Python\three_server\venv\lib\site-packages\django\core\handlers\exception.py", line 34, in inner
    response = get_response(request)
  File "D:\WorkSpase\Python\three_server\venv\lib\site-packages\django\core\handlers\base.py", line 115, in _get_response
    response = self.process_exception_by_middleware(e, request)
  File "D:\WorkSpase\Python\three_server\venv\lib\site-packages\django\core\handlers\base.py", line 113, in _get_response
    response = wrapped_callback(request, *callback_args, **callback_kwargs)
  File "D:\WorkSpase\Python\three_server\venv\lib\site-packages\django\views\generic\base.py", line 71, in view
    return self.dispatch(request, *args, **kwargs)
  File "D:\WorkSpase\Python\three_server\three_server\base\controller.py", line 98, in dispatch
    return handler()
  File "D:\WorkSpase\Python\three_server\finance\api\client_pay.py", line 119, in recharge
    test(10)
  File "D:\WorkSpase\Python\three_server\finance\biz\server_recharge_record.py", line 44, in test
    if int(info['range'][0]) < now_time < int(info['range'][1]):
TypeError: string indices must be integers
[2019-10-20 13:01:20,621][MainThread:11648][task_id:django.channels.server][runserver.py:154][ERROR][HTTP GET /three/finance/pay/recharge 500 [0.09, 127.0.0.1:3115]]
[2019-10-20 13:04:19,332][Thread-2:18104][task_id:django.request][log.py:228][ERROR][Internal Server Error: /three/finance/pay/recharge]
Traceback (most recent call last):
  File "D:\WorkSpase\Python\three_server\venv\lib\site-packages\django\core\handlers\exception.py", line 34, in inner
    response = get_response(request)
  File "D:\WorkSpase\Python\three_server\venv\lib\site-packages\django\core\handlers\base.py", line 115, in _get_response
    response = self.process_exception_by_middleware(e, request)
  File "D:\WorkSpase\Python\three_server\venv\lib\site-packages\django\core\handlers\base.py", line 113, in _get_response
    response = wrapped_callback(request, *callback_args, **callback_kwargs)
  File "D:\WorkSpase\Python\three_server\venv\lib\site-packages\django\views\generic\base.py", line 71, in view
    return self.dispatch(request, *args, **kwargs)
  File "D:\WorkSpase\Python\three_server\three_server\base\controller.py", line 98, in dispatch
    return handler()
  File "D:\WorkSpase\Python\three_server\finance\api\client_pay.py", line 119, in recharge
    test(10)
  File "D:\WorkSpase\Python\three_server\finance\biz\server_recharge_record.py", line 49, in test
    if v['min'] < value < v['max']:
TypeError: unorderable types: str() < int()
[2019-10-20 13:04:19,334][MainThread:5676][task_id:django.channels.server][runserver.py:154][ERROR][HTTP GET /three/finance/pay/recharge 500 [0.09, 127.0.0.1:3262]]
[2019-10-20 19:14:54,947][MainThread:140215313491712][task_id:celery.utils.dispatch.signal][signal.py:293][ERROR][Signal handler <bound method DjangoFixup.on_import_modules of <celery.fixups.django.DjangoFixup object at 0x7f866a17f050>> raised: ModuleNotFoundError("No module named 'django_celery_results'")]
Traceback (most recent call last):
  File "/usr/anaconda3/lib/python3.7/site-packages/celery/utils/dispatch/signal.py", line 288, in send
    response = receiver(signal=self, sender=sender, **named)
  File "/usr/anaconda3/lib/python3.7/site-packages/celery/fixups/django.py", line 84, in on_import_modules
    self.worker_fixup.validate_models()
  File "/usr/anaconda3/lib/python3.7/site-packages/celery/fixups/django.py", line 122, in validate_models
    self.django_setup()
  File "/usr/anaconda3/lib/python3.7/site-packages/celery/fixups/django.py", line 118, in django_setup
    django.setup()
  File "/usr/anaconda3/lib/python3.7/site-packages/django/__init__.py", line 24, in setup
    apps.populate(settings.INSTALLED_APPS)
  File "/usr/anaconda3/lib/python3.7/site-packages/django/apps/registry.py", line 91, in populate
    app_config = AppConfig.create(entry)
  File "/usr/anaconda3/lib/python3.7/site-packages/django/apps/config.py", line 90, in create
    module = import_module(entry)
  File "/usr/anaconda3/lib/python3.7/importlib/__init__.py", line 127, in import_module
    return _bootstrap._gcd_import(name[level:], package, level)
  File "<frozen importlib._bootstrap>", line 1006, in _gcd_import
  File "<frozen importlib._bootstrap>", line 983, in _find_and_load
  File "<frozen importlib._bootstrap>", line 965, in _find_and_load_unlocked
ModuleNotFoundError: No module named 'django_celery_results'
[2019-10-20 19:14:54,948][MainThread:140215313491712][task_id:celery.utils.dispatch.signal][signal.py:293][ERROR][Signal handler <promise@0x7f866a11ba50 --> <bound method Celery._autodiscover_tasks of <Celery three_server at 0x7f866a175d90>>> raised: AppRegistryNotReady("Apps aren't loaded yet.")]
Traceback (most recent call last):
  File "/usr/anaconda3/lib/python3.7/site-packages/celery/utils/dispatch/signal.py", line 288, in send
    response = receiver(signal=self, sender=sender, **named)
  File "/usr/anaconda3/lib/python3.7/site-packages/vine/promises.py", line 170, in __call__
    return self.throw()
  File "/usr/anaconda3/lib/python3.7/site-packages/vine/promises.py", line 167, in __call__
    retval = fun(*final_args, **final_kwargs)
  File "/usr/anaconda3/lib/python3.7/site-packages/celery/app/base.py", line 680, in _autodiscover_tasks
    return self._autodiscover_tasks_from_fixups(related_name)
  File "/usr/anaconda3/lib/python3.7/site-packages/celery/app/base.py", line 690, in _autodiscover_tasks_from_fixups
    pkg for fixup in self._fixups
  File "/usr/anaconda3/lib/python3.7/site-packages/celery/app/base.py", line 691, in <listcomp>
    for pkg in fixup.autodiscover_tasks()
  File "/usr/anaconda3/lib/python3.7/site-packages/celery/fixups/django.py", line 94, in autodiscover_tasks
    return [config.name for config in apps.get_app_configs()]
  File "/usr/anaconda3/lib/python3.7/site-packages/django/apps/registry.py", line 144, in get_app_configs
    self.check_apps_ready()
  File "/usr/anaconda3/lib/python3.7/site-packages/django/apps/registry.py", line 135, in check_apps_ready
    raise AppRegistryNotReady("Apps aren't loaded yet.")
django.core.exceptions.AppRegistryNotReady: Apps aren't loaded yet.
[2019-10-20 19:14:56,761][MainThread:139791956715264][task_id:celery.utils.dispatch.signal][signal.py:293][ERROR][Signal handler <bound method DjangoFixup.on_import_modules of <celery.fixups.django.DjangoFixup object at 0x7f23d73bc890>> raised: ModuleNotFoundError("No module named 'django_celery_results'")]
Traceback (most recent call last):
  File "/usr/anaconda3/lib/python3.7/site-packages/celery/utils/dispatch/signal.py", line 288, in send
    response = receiver(signal=self, sender=sender, **named)
  File "/usr/anaconda3/lib/python3.7/site-packages/celery/fixups/django.py", line 84, in on_import_modules
    self.worker_fixup.validate_models()
  File "/usr/anaconda3/lib/python3.7/site-packages/celery/fixups/django.py", line 122, in validate_models
    self.django_setup()
  File "/usr/anaconda3/lib/python3.7/site-packages/celery/fixups/django.py", line 118, in django_setup
    django.setup()
  File "/usr/anaconda3/lib/python3.7/site-packages/django/__init__.py", line 24, in setup
    apps.populate(settings.INSTALLED_APPS)
  File "/usr/anaconda3/lib/python3.7/site-packages/django/apps/registry.py", line 91, in populate
    app_config = AppConfig.create(entry)
  File "/usr/anaconda3/lib/python3.7/site-packages/django/apps/config.py", line 90, in create
    module = import_module(entry)
  File "/usr/anaconda3/lib/python3.7/importlib/__init__.py", line 127, in import_module
    return _bootstrap._gcd_import(name[level:], package, level)
  File "<frozen importlib._bootstrap>", line 1006, in _gcd_import
  File "<frozen importlib._bootstrap>", line 983, in _find_and_load
  File "<frozen importlib._bootstrap>", line 965, in _find_and_load_unlocked
ModuleNotFoundError: No module named 'django_celery_results'
[2019-10-20 19:14:56,762][MainThread:139791956715264][task_id:celery.utils.dispatch.signal][signal.py:293][ERROR][Signal handler <promise@0x7f23d8104a50 --> <bound method Celery._autodiscover_tasks of <Celery three_server at 0x7f23d80e1910>>> raised: AppRegistryNotReady("Apps aren't loaded yet.")]
Traceback (most recent call last):
  File "/usr/anaconda3/lib/python3.7/site-packages/celery/utils/dispatch/signal.py", line 288, in send
    response = receiver(signal=self, sender=sender, **named)
  File "/usr/anaconda3/lib/python3.7/site-packages/vine/promises.py", line 170, in __call__
    return self.throw()
  File "/usr/anaconda3/lib/python3.7/site-packages/vine/promises.py", line 167, in __call__
    retval = fun(*final_args, **final_kwargs)
  File "/usr/anaconda3/lib/python3.7/site-packages/celery/app/base.py", line 680, in _autodiscover_tasks
    return self._autodiscover_tasks_from_fixups(related_name)
  File "/usr/anaconda3/lib/python3.7/site-packages/celery/app/base.py", line 690, in _autodiscover_tasks_from_fixups
    pkg for fixup in self._fixups
  File "/usr/anaconda3/lib/python3.7/site-packages/celery/app/base.py", line 691, in <listcomp>
    for pkg in fixup.autodiscover_tasks()
  File "/usr/anaconda3/lib/python3.7/site-packages/celery/fixups/django.py", line 94, in autodiscover_tasks
    return [config.name for config in apps.get_app_configs()]
  File "/usr/anaconda3/lib/python3.7/site-packages/django/apps/registry.py", line 144, in get_app_configs
    self.check_apps_ready()
  File "/usr/anaconda3/lib/python3.7/site-packages/django/apps/registry.py", line 135, in check_apps_ready
    raise AppRegistryNotReady("Apps aren't loaded yet.")
django.core.exceptions.AppRegistryNotReady: Apps aren't loaded yet.
[2019-10-20 19:14:59,599][MainThread:139828286334720][task_id:celery.utils.dispatch.signal][signal.py:293][ERROR][Signal handler <bound method DjangoFixup.on_import_modules of <celery.fixups.django.DjangoFixup object at 0x7f2c4d781b10>> raised: ModuleNotFoundError("No module named 'django_celery_results'")]
Traceback (most recent call last):
  File "/usr/anaconda3/lib/python3.7/site-packages/celery/utils/dispatch/signal.py", line 288, in send
    response = receiver(signal=self, sender=sender, **named)
  File "/usr/anaconda3/lib/python3.7/site-packages/celery/fixups/django.py", line 84, in on_import_modules
    self.worker_fixup.validate_models()
  File "/usr/anaconda3/lib/python3.7/site-packages/celery/fixups/django.py", line 122, in validate_models
    self.django_setup()
  File "/usr/anaconda3/lib/python3.7/site-packages/celery/fixups/django.py", line 118, in django_setup
    django.setup()
  File "/usr/anaconda3/lib/python3.7/site-packages/django/__init__.py", line 24, in setup
    apps.populate(settings.INSTALLED_APPS)
  File "/usr/anaconda3/lib/python3.7/site-packages/django/apps/registry.py", line 91, in populate
    app_config = AppConfig.create(entry)
  File "/usr/anaconda3/lib/python3.7/site-packages/django/apps/config.py", line 90, in create
    module = import_module(entry)
  File "/usr/anaconda3/lib/python3.7/importlib/__init__.py", line 127, in import_module
    return _bootstrap._gcd_import(name[level:], package, level)
  File "<frozen importlib._bootstrap>", line 1006, in _gcd_import
  File "<frozen importlib._bootstrap>", line 983, in _find_and_load
  File "<frozen importlib._bootstrap>", line 965, in _find_and_load_unlocked
ModuleNotFoundError: No module named 'django_celery_results'
[2019-10-20 19:14:59,600][MainThread:139828286334720][task_id:celery.utils.dispatch.signal][signal.py:293][ERROR][Signal handler <promise@0x7f2c4d7a4a50 --> <bound method Celery._autodiscover_tasks of <Celery three_server at 0x7f2c4d781950>>> raised: AppRegistryNotReady("Apps aren't loaded yet.")]
Traceback (most recent call last):
  File "/usr/anaconda3/lib/python3.7/site-packages/celery/utils/dispatch/signal.py", line 288, in send
    response = receiver(signal=self, sender=sender, **named)
  File "/usr/anaconda3/lib/python3.7/site-packages/vine/promises.py", line 170, in __call__
    return self.throw()
  File "/usr/anaconda3/lib/python3.7/site-packages/vine/promises.py", line 167, in __call__
    retval = fun(*final_args, **final_kwargs)
  File "/usr/anaconda3/lib/python3.7/site-packages/celery/app/base.py", line 680, in _autodiscover_tasks
    return self._autodiscover_tasks_from_fixups(related_name)
  File "/usr/anaconda3/lib/python3.7/site-packages/celery/app/base.py", line 690, in _autodiscover_tasks_from_fixups
    pkg for fixup in self._fixups
  File "/usr/anaconda3/lib/python3.7/site-packages/celery/app/base.py", line 691, in <listcomp>
    for pkg in fixup.autodiscover_tasks()
  File "/usr/anaconda3/lib/python3.7/site-packages/celery/fixups/django.py", line 94, in autodiscover_tasks
    return [config.name for config in apps.get_app_configs()]
  File "/usr/anaconda3/lib/python3.7/site-packages/django/apps/registry.py", line 144, in get_app_configs
    self.check_apps_ready()
  File "/usr/anaconda3/lib/python3.7/site-packages/django/apps/registry.py", line 135, in check_apps_ready
    raise AppRegistryNotReady("Apps aren't loaded yet.")
django.core.exceptions.AppRegistryNotReady: Apps aren't loaded yet.
[2019-10-20 19:15:04,178][MainThread:140463373215488][task_id:celery.utils.dispatch.signal][signal.py:293][ERROR][Signal handler <bound method DjangoFixup.on_import_modules of <celery.fixups.django.DjangoFixup object at 0x7fc02b98dc90>> raised: ModuleNotFoundError("No module named 'django_celery_results'")]
Traceback (most recent call last):
  File "/usr/anaconda3/lib/python3.7/site-packages/celery/utils/dispatch/signal.py", line 288, in send
    response = receiver(signal=self, sender=sender, **named)
  File "/usr/anaconda3/lib/python3.7/site-packages/celery/fixups/django.py", line 84, in on_import_modules
    self.worker_fixup.validate_models()
  File "/usr/anaconda3/lib/python3.7/site-packages/celery/fixups/django.py", line 122, in validate_models
    self.django_setup()
  File "/usr/anaconda3/lib/python3.7/site-packages/celery/fixups/django.py", line 118, in django_setup
    django.setup()
  File "/usr/anaconda3/lib/python3.7/site-packages/django/__init__.py", line 24, in setup
    apps.populate(settings.INSTALLED_APPS)
  File "/usr/anaconda3/lib/python3.7/site-packages/django/apps/registry.py", line 91, in populate
    app_config = AppConfig.create(entry)
  File "/usr/anaconda3/lib/python3.7/site-packages/django/apps/config.py", line 90, in create
    module = import_module(entry)
  File "/usr/anaconda3/lib/python3.7/importlib/__init__.py", line 127, in import_module
    return _bootstrap._gcd_import(name[level:], package, level)
  File "<frozen importlib._bootstrap>", line 1006, in _gcd_import
  File "<frozen importlib._bootstrap>", line 983, in _find_and_load
  File "<frozen importlib._bootstrap>", line 965, in _find_and_load_unlocked
ModuleNotFoundError: No module named 'django_celery_results'
[2019-10-20 19:15:04,179][MainThread:140463373215488][task_id:celery.utils.dispatch.signal][signal.py:293][ERROR][Signal handler <promise@0x7fc02b9b0a50 --> <bound method Celery._autodiscover_tasks of <Celery three_server at 0x7fc02b98dad0>>> raised: AppRegistryNotReady("Apps aren't loaded yet.")]
Traceback (most recent call last):
  File "/usr/anaconda3/lib/python3.7/site-packages/celery/utils/dispatch/signal.py", line 288, in send
    response = receiver(signal=self, sender=sender, **named)
  File "/usr/anaconda3/lib/python3.7/site-packages/vine/promises.py", line 170, in __call__
    return self.throw()
  File "/usr/anaconda3/lib/python3.7/site-packages/vine/promises.py", line 167, in __call__
    retval = fun(*final_args, **final_kwargs)
  File "/usr/anaconda3/lib/python3.7/site-packages/celery/app/base.py", line 680, in _autodiscover_tasks
    return self._autodiscover_tasks_from_fixups(related_name)
  File "/usr/anaconda3/lib/python3.7/site-packages/celery/app/base.py", line 690, in _autodiscover_tasks_from_fixups
    pkg for fixup in self._fixups
  File "/usr/anaconda3/lib/python3.7/site-packages/celery/app/base.py", line 691, in <listcomp>
    for pkg in fixup.autodiscover_tasks()
  File "/usr/anaconda3/lib/python3.7/site-packages/celery/fixups/django.py", line 94, in autodiscover_tasks
    return [config.name for config in apps.get_app_configs()]
  File "/usr/anaconda3/lib/python3.7/site-packages/django/apps/registry.py", line 144, in get_app_configs
    self.check_apps_ready()
  File "/usr/anaconda3/lib/python3.7/site-packages/django/apps/registry.py", line 135, in check_apps_ready
    raise AppRegistryNotReady("Apps aren't loaded yet.")
django.core.exceptions.AppRegistryNotReady: Apps aren't loaded yet.
[2019-10-20 19:28:52,335][Thread-12:139655055914752][task_id:django.request][log.py:228][ERROR][Internal Server Error: /api/setting/recharge/info]
Traceback (most recent call last):
  File "/usr/anaconda3/envs/three_server/lib/python3.5/site-packages/django/core/handlers/exception.py", line 34, in inner
    response = get_response(request)
  File "/usr/anaconda3/envs/three_server/lib/python3.5/site-packages/django/core/handlers/base.py", line 115, in _get_response
    response = self.process_exception_by_middleware(e, request)
  File "/usr/anaconda3/envs/three_server/lib/python3.5/site-packages/django/core/handlers/base.py", line 113, in _get_response
    response = wrapped_callback(request, *callback_args, **callback_kwargs)
  File "/usr/anaconda3/envs/three_server/lib/python3.5/site-packages/django/views/generic/base.py", line 71, in view
    return self.dispatch(request, *args, **kwargs)
  File "/shiw/three_server/three_server/base/controller.py", line 98, in dispatch
    return handler()
  File "/shiw/three_server/game_setting/api/server_recharge.py", line 31, in info
    data = info()
  File "/shiw/three_server/game_setting/biz/server_recharge.py", line 38, in info
    "info": {} if obj_info is None else json.loads(obj_info)
  File "/usr/anaconda3/envs/three_server/lib/python3.5/json/__init__.py", line 312, in loads
    s.__class__.__name__))
TypeError: the JSON object must be str, not 'dict'
[2019-10-20 19:28:52,338][django-main-thread:139655721903872][task_id:django.channels.server][runserver.py:154][ERROR][HTTP GET /api/setting/recharge/info 500 [0.05, 134.159.149.3:10749]]
