[2019-10-09 14:52:35,464][django-main-thread:140230537258752][task_id:daphne.server][server.py:157][CRITICAL][Listen failure: Couldn't listen on 0.0.0.0:9090: [Errno 98] Address already in use.]
[2019-10-09 14:57:50,050][django-main-thread:140106660185856][task_id:daphne.server][server.py:157][CRITICAL][Listen failure: Couldn't listen on 0.0.0.0:9090: [Errno 98] Address already in use.]
[2019-10-09 15:00:24,617][django-main-thread:140709694715648][task_id:daphne.server][server.py:157][CRITICAL][Listen failure: Couldn't listen on 0.0.0.0:9090: [Errno 98] Address already in use.]
[2019-10-10 14:44:23,981][Thread-8:140120934041344][task_id:django.request][log.py:228][ERROR][Internal Server Error: /api/hall/hall/switch]
Traceback (most recent call last):
  File "/usr/anaconda3/envs/three_server/lib/python3.5/site-packages/django/core/handlers/exception.py", line 34, in inner
    response = get_response(request)
  File "/usr/anaconda3/envs/three_server/lib/python3.5/site-packages/django/core/handlers/base.py", line 115, in _get_response
    response = self.process_exception_by_middleware(e, request)
  File "/usr/anaconda3/envs/three_server/lib/python3.5/site-packages/django/core/handlers/base.py", line 113, in _get_response
    response = wrapped_callback(request, *callback_args, **callback_kwargs)
  File "/usr/anaconda3/envs/three_server/lib/python3.5/site-packages/django/views/generic/base.py", line 71, in view
    return self.dispatch(request, *args, **kwargs)
  File "/shiw/three_server/three_server/base/controller.py", line 98, in dispatch
    return handler()
  File "/shiw/three_server/hall/api/server_hall.py", line 30, in switch
    start_stage.delay(hall.id, hall.tag)
  File "/usr/anaconda3/envs/three_server/lib/python3.5/site-packages/celery/app/task.py", line 461, in delay
    return self.apply_async(args, kwargs)
  File "/usr/anaconda3/envs/three_server/lib/python3.5/site-packages/celery/app/task.py", line 573, in apply_async
    **dict(self._get_exec_options(), **options)
  File "/usr/anaconda3/envs/three_server/lib/python3.5/site-packages/celery/app/base.py", line 354, in send_task
    reply_to=reply_to or self.oid, **options
  File "/usr/anaconda3/envs/three_server/lib/python3.5/site-packages/celery/app/amqp.py", line 310, in publish_task
    **kwargs
  File "/usr/anaconda3/envs/three_server/lib/python3.5/site-packages/kombu/messaging.py", line 172, in publish
    routing_key, mandatory, immediate, exchange, declare)
  File "/usr/anaconda3/envs/three_server/lib/python3.5/site-packages/kombu/connection.py", line 449, in _ensured
    return fun(*args, **kwargs)
  File "/usr/anaconda3/envs/three_server/lib/python3.5/site-packages/kombu/messaging.py", line 188, in _publish
    mandatory=mandatory, immediate=immediate,
  File "/usr/anaconda3/envs/three_server/lib/python3.5/site-packages/kombu/transport/virtual/__init__.py", line 521, in basic_publish
    message, exchange, routing_key, **kwargs
  File "/usr/anaconda3/envs/three_server/lib/python3.5/site-packages/kombu/transport/virtual/exchange.py", line 60, in deliver
    for queue in _lookup(exchange, routing_key):
  File "/usr/anaconda3/envs/three_server/lib/python3.5/site-packages/kombu/transport/virtual/__init__.py", line 612, in _lookup
    self.get_table(exchange),
  File "/usr/anaconda3/envs/three_server/lib/python3.5/site-packages/kombu/transport/redis.py", line 760, in get_table
    raise InconsistencyError(NO_ROUTE_ERROR.format(exchange, key))
kombu.exceptions.InconsistencyError: 
Cannot route message for exchange 'celery': Table empty or key no longer exists.
Probably the key ('_kombu.binding.celery') has been removed from the Redis database.

[2019-10-10 14:44:23,986][django-main-thread:140121357780736][task_id:django.channels.server][runserver.py:154][ERROR][[35;1mHTTP GET /api/hall/hall/switch?obj_id=1 500 [0.09, 134.159.149.3:3275][0m]
[2019-10-10 14:44:45,634][Thread-5:140120959219456][task_id:django.request][log.py:228][ERROR][Internal Server Error: /api/hall/hall/switch]
Traceback (most recent call last):
  File "/usr/anaconda3/envs/three_server/lib/python3.5/site-packages/django/core/handlers/exception.py", line 34, in inner
    response = get_response(request)
  File "/usr/anaconda3/envs/three_server/lib/python3.5/site-packages/django/core/handlers/base.py", line 115, in _get_response
    response = self.process_exception_by_middleware(e, request)
  File "/usr/anaconda3/envs/three_server/lib/python3.5/site-packages/django/core/handlers/base.py", line 113, in _get_response
    response = wrapped_callback(request, *callback_args, **callback_kwargs)
  File "/usr/anaconda3/envs/three_server/lib/python3.5/site-packages/django/views/generic/base.py", line 71, in view
    return self.dispatch(request, *args, **kwargs)
  File "/shiw/three_server/three_server/base/controller.py", line 98, in dispatch
    return handler()
  File "/shiw/three_server/hall/api/server_hall.py", line 30, in switch
    start_stage.delay(hall.id, hall.tag)
  File "/usr/anaconda3/envs/three_server/lib/python3.5/site-packages/celery/app/task.py", line 461, in delay
    return self.apply_async(args, kwargs)
  File "/usr/anaconda3/envs/three_server/lib/python3.5/site-packages/celery/app/task.py", line 573, in apply_async
    **dict(self._get_exec_options(), **options)
  File "/usr/anaconda3/envs/three_server/lib/python3.5/site-packages/celery/app/base.py", line 354, in send_task
    reply_to=reply_to or self.oid, **options
  File "/usr/anaconda3/envs/three_server/lib/python3.5/site-packages/celery/app/amqp.py", line 310, in publish_task
    **kwargs
  File "/usr/anaconda3/envs/three_server/lib/python3.5/site-packages/kombu/messaging.py", line 172, in publish
    routing_key, mandatory, immediate, exchange, declare)
  File "/usr/anaconda3/envs/three_server/lib/python3.5/site-packages/kombu/connection.py", line 449, in _ensured
    return fun(*args, **kwargs)
  File "/usr/anaconda3/envs/three_server/lib/python3.5/site-packages/kombu/messaging.py", line 188, in _publish
    mandatory=mandatory, immediate=immediate,
  File "/usr/anaconda3/envs/three_server/lib/python3.5/site-packages/kombu/transport/virtual/__init__.py", line 521, in basic_publish
    message, exchange, routing_key, **kwargs
  File "/usr/anaconda3/envs/three_server/lib/python3.5/site-packages/kombu/transport/virtual/exchange.py", line 60, in deliver
    for queue in _lookup(exchange, routing_key):
  File "/usr/anaconda3/envs/three_server/lib/python3.5/site-packages/kombu/transport/virtual/__init__.py", line 612, in _lookup
    self.get_table(exchange),
  File "/usr/anaconda3/envs/three_server/lib/python3.5/site-packages/kombu/transport/redis.py", line 760, in get_table
    raise InconsistencyError(NO_ROUTE_ERROR.format(exchange, key))
kombu.exceptions.InconsistencyError: 
Cannot route message for exchange 'celery': Table empty or key no longer exists.
Probably the key ('_kombu.binding.celery') has been removed from the Redis database.

[2019-10-10 14:44:45,637][django-main-thread:140121357780736][task_id:django.channels.server][runserver.py:154][ERROR][[35;1mHTTP GET /api/hall/hall/switch?obj_id=1 500 [0.07, 134.159.149.3:3275][0m]
